2017-09-23 15:44:40,868 [b'uWSGIWorker3Core3':140290100131584] [django.request:124] [exception:handle_uncaught_exception] [ERROR]- Internal Server Error: /djangowagtail搭建博客/1wagtail建站分析及博客功能脑图/
Traceback (most recent call last):
  File "/home/cityblack1/sites/www.cityblack1.cc/nb/lib/python3.4/site-packages/django/db/backends/utils.py", line 64, in execute
    return self.cursor.execute(sql, params)
  File "/home/cityblack1/sites/www.cityblack1.cc/nb/lib/python3.4/site-packages/django/db/backends/sqlite3/base.py", line 337, in execute
    return Database.Cursor.execute(self, query, params)
sqlite3.OperationalError: no such table: wagtailcore_site

The above exception was the direct cause of the following exception:

Traceback (most recent call last):
  File "/home/cityblack1/sites/www.cityblack1.cc/nb/lib/python3.4/site-packages/django/core/handlers/exception.py", line 39, in inner
    response = get_response(request)
  File "/home/cityblack1/sites/www.cityblack1.cc/nb/lib/python3.4/site-packages/django/utils/deprecation.py", line 122, in __call__
    response = self.process_request(request)
  File "/home/cityblack1/sites/www.cityblack1.cc/nb/lib/python3.4/site-packages/wagtail/wagtailcore/middleware.py", line 20, in process_request
    request.site = Site.find_for_request(request)
  File "/home/cityblack1/sites/www.cityblack1.cc/nb/lib/python3.4/site-packages/wagtail/wagtailcore/models.py", line 129, in find_for_request
    return get_site_for_hostname(hostname, port)
  File "/home/cityblack1/sites/www.cityblack1.cc/nb/lib/python3.4/site-packages/wagtail/wagtailcore/sites.py", line 38, in get_site_for_hostname
    'root_page'
  File "/home/cityblack1/sites/www.cityblack1.cc/nb/lib/python3.4/site-packages/django/db/models/query.py", line 256, in __iter__
    self._fetch_all()
  File "/home/cityblack1/sites/www.cityblack1.cc/nb/lib/python3.4/site-packages/django/db/models/query.py", line 1085, in _fetch_all
    self._result_cache = list(self.iterator())
  File "/home/cityblack1/sites/www.cityblack1.cc/nb/lib/python3.4/site-packages/django/db/models/query.py", line 54, in __iter__
    results = compiler.execute_sql()
  File "/home/cityblack1/sites/www.cityblack1.cc/nb/lib/python3.4/site-packages/django/db/models/sql/compiler.py", line 835, in execute_sql
    cursor.execute(sql, params)
  File "/home/cityblack1/sites/www.cityblack1.cc/nb/lib/python3.4/site-packages/django/db/backends/utils.py", line 64, in execute
    return self.cursor.execute(sql, params)
  File "/home/cityblack1/sites/www.cityblack1.cc/nb/lib/python3.4/site-packages/django/db/utils.py", line 94, in __exit__
    six.reraise(dj_exc_type, dj_exc_value, traceback)
  File "/home/cityblack1/sites/www.cityblack1.cc/nb/lib/python3.4/site-packages/django/utils/six.py", line 685, in reraise
    raise value.with_traceback(tb)
  File "/home/cityblack1/sites/www.cityblack1.cc/nb/lib/python3.4/site-packages/django/db/backends/utils.py", line 64, in execute
    return self.cursor.execute(sql, params)
  File "/home/cityblack1/sites/www.cityblack1.cc/nb/lib/python3.4/site-packages/django/db/backends/sqlite3/base.py", line 337, in execute
    return Database.Cursor.execute(self, query, params)
django.db.utils.OperationalError: no such table: wagtailcore_site
2017-09-23 15:44:41,860 [b'uWSGIWorker3Core1':140290116916992] [django.request:124] [exception:handle_uncaught_exception] [ERROR]- Internal Server Error: /djangowagtail搭建博客/1wagtail建站分析及博客功能脑图/
Traceback (most recent call last):
  File "/home/cityblack1/sites/www.cityblack1.cc/nb/lib/python3.4/site-packages/django/db/backends/utils.py", line 64, in execute
    return self.cursor.execute(sql, params)
  File "/home/cityblack1/sites/www.cityblack1.cc/nb/lib/python3.4/site-packages/django/db/backends/sqlite3/base.py", line 337, in execute
    return Database.Cursor.execute(self, query, params)
sqlite3.OperationalError: no such table: wagtailcore_site

The above exception was the direct cause of the following exception:

Traceback (most recent call last):
  File "/home/cityblack1/sites/www.cityblack1.cc/nb/lib/python3.4/site-packages/django/core/handlers/exception.py", line 39, in inner
    response = get_response(request)
  File "/home/cityblack1/sites/www.cityblack1.cc/nb/lib/python3.4/site-packages/django/utils/deprecation.py", line 122, in __call__
    response = self.process_request(request)
  File "/home/cityblack1/sites/www.cityblack1.cc/nb/lib/python3.4/site-packages/wagtail/wagtailcore/middleware.py", line 20, in process_request
    request.site = Site.find_for_request(request)
  File "/home/cityblack1/sites/www.cityblack1.cc/nb/lib/python3.4/site-packages/wagtail/wagtailcore/models.py", line 129, in find_for_request
    return get_site_for_hostname(hostname, port)
  File "/home/cityblack1/sites/www.cityblack1.cc/nb/lib/python3.4/site-packages/wagtail/wagtailcore/sites.py", line 38, in get_site_for_hostname
    'root_page'
  File "/home/cityblack1/sites/www.cityblack1.cc/nb/lib/python3.4/site-packages/django/db/models/query.py", line 256, in __iter__
    self._fetch_all()
  File "/home/cityblack1/sites/www.cityblack1.cc/nb/lib/python3.4/site-packages/django/db/models/query.py", line 1085, in _fetch_all
    self._result_cache = list(self.iterator())
  File "/home/cityblack1/sites/www.cityblack1.cc/nb/lib/python3.4/site-packages/django/db/models/query.py", line 54, in __iter__
    results = compiler.execute_sql()
  File "/home/cityblack1/sites/www.cityblack1.cc/nb/lib/python3.4/site-packages/django/db/models/sql/compiler.py", line 835, in execute_sql
    cursor.execute(sql, params)
  File "/home/cityblack1/sites/www.cityblack1.cc/nb/lib/python3.4/site-packages/django/db/backends/utils.py", line 64, in execute
    return self.cursor.execute(sql, params)
  File "/home/cityblack1/sites/www.cityblack1.cc/nb/lib/python3.4/site-packages/django/db/utils.py", line 94, in __exit__
    six.reraise(dj_exc_type, dj_exc_value, traceback)
  File "/home/cityblack1/sites/www.cityblack1.cc/nb/lib/python3.4/site-packages/django/utils/six.py", line 685, in reraise
    raise value.with_traceback(tb)
  File "/home/cityblack1/sites/www.cityblack1.cc/nb/lib/python3.4/site-packages/django/db/backends/utils.py", line 64, in execute
    return self.cursor.execute(sql, params)
  File "/home/cityblack1/sites/www.cityblack1.cc/nb/lib/python3.4/site-packages/django/db/backends/sqlite3/base.py", line 337, in execute
    return Database.Cursor.execute(self, query, params)
django.db.utils.OperationalError: no such table: wagtailcore_site
2017-09-23 15:44:42,782 [b'uWSGIWorker3Core2':140290108524288] [django.request:124] [exception:handle_uncaught_exception] [ERROR]- Internal Server Error: /djangowagtail搭建博客/1wagtail建站分析及博客功能脑图/
Traceback (most recent call last):
  File "/home/cityblack1/sites/www.cityblack1.cc/nb/lib/python3.4/site-packages/django/db/backends/utils.py", line 64, in execute
    return self.cursor.execute(sql, params)
  File "/home/cityblack1/sites/www.cityblack1.cc/nb/lib/python3.4/site-packages/django/db/backends/sqlite3/base.py", line 337, in execute
    return Database.Cursor.execute(self, query, params)
sqlite3.OperationalError: no such table: wagtailcore_site

The above exception was the direct cause of the following exception:

Traceback (most recent call last):
  File "/home/cityblack1/sites/www.cityblack1.cc/nb/lib/python3.4/site-packages/django/core/handlers/exception.py", line 39, in inner
    response = get_response(request)
  File "/home/cityblack1/sites/www.cityblack1.cc/nb/lib/python3.4/site-packages/django/utils/deprecation.py", line 122, in __call__
    response = self.process_request(request)
  File "/home/cityblack1/sites/www.cityblack1.cc/nb/lib/python3.4/site-packages/wagtail/wagtailcore/middleware.py", line 20, in process_request
    request.site = Site.find_for_request(request)
  File "/home/cityblack1/sites/www.cityblack1.cc/nb/lib/python3.4/site-packages/wagtail/wagtailcore/models.py", line 129, in find_for_request
    return get_site_for_hostname(hostname, port)
  File "/home/cityblack1/sites/www.cityblack1.cc/nb/lib/python3.4/site-packages/wagtail/wagtailcore/sites.py", line 38, in get_site_for_hostname
    'root_page'
  File "/home/cityblack1/sites/www.cityblack1.cc/nb/lib/python3.4/site-packages/django/db/models/query.py", line 256, in __iter__
    self._fetch_all()
  File "/home/cityblack1/sites/www.cityblack1.cc/nb/lib/python3.4/site-packages/django/db/models/query.py", line 1085, in _fetch_all
    self._result_cache = list(self.iterator())
  File "/home/cityblack1/sites/www.cityblack1.cc/nb/lib/python3.4/site-packages/django/db/models/query.py", line 54, in __iter__
    results = compiler.execute_sql()
  File "/home/cityblack1/sites/www.cityblack1.cc/nb/lib/python3.4/site-packages/django/db/models/sql/compiler.py", line 835, in execute_sql
    cursor.execute(sql, params)
  File "/home/cityblack1/sites/www.cityblack1.cc/nb/lib/python3.4/site-packages/django/db/backends/utils.py", line 64, in execute
    return self.cursor.execute(sql, params)
  File "/home/cityblack1/sites/www.cityblack1.cc/nb/lib/python3.4/site-packages/django/db/utils.py", line 94, in __exit__
    six.reraise(dj_exc_type, dj_exc_value, traceback)
  File "/home/cityblack1/sites/www.cityblack1.cc/nb/lib/python3.4/site-packages/django/utils/six.py", line 685, in reraise
    raise value.with_traceback(tb)
  File "/home/cityblack1/sites/www.cityblack1.cc/nb/lib/python3.4/site-packages/django/db/backends/utils.py", line 64, in execute
    return self.cursor.execute(sql, params)
  File "/home/cityblack1/sites/www.cityblack1.cc/nb/lib/python3.4/site-packages/django/db/backends/sqlite3/base.py", line 337, in execute
    return Database.Cursor.execute(self, query, params)
django.db.utils.OperationalError: no such table: wagtailcore_site
2017-09-23 15:44:43,592 [b'uWSGIWorker3Core0':140290216888128] [django.request:124] [exception:handle_uncaught_exception] [ERROR]- Internal Server Error: /djangowagtail搭建博客/1wagtail建站分析及博客功能脑图/
Traceback (most recent call last):
  File "/home/cityblack1/sites/www.cityblack1.cc/nb/lib/python3.4/site-packages/django/db/backends/utils.py", line 64, in execute
    return self.cursor.execute(sql, params)
  File "/home/cityblack1/sites/www.cityblack1.cc/nb/lib/python3.4/site-packages/django/db/backends/sqlite3/base.py", line 337, in execute
    return Database.Cursor.execute(self, query, params)
sqlite3.OperationalError: no such table: wagtailcore_site

The above exception was the direct cause of the following exception:

Traceback (most recent call last):
  File "/home/cityblack1/sites/www.cityblack1.cc/nb/lib/python3.4/site-packages/django/core/handlers/exception.py", line 39, in inner
    response = get_response(request)
  File "/home/cityblack1/sites/www.cityblack1.cc/nb/lib/python3.4/site-packages/django/utils/deprecation.py", line 122, in __call__
    response = self.process_request(request)
  File "/home/cityblack1/sites/www.cityblack1.cc/nb/lib/python3.4/site-packages/wagtail/wagtailcore/middleware.py", line 20, in process_request
    request.site = Site.find_for_request(request)
  File "/home/cityblack1/sites/www.cityblack1.cc/nb/lib/python3.4/site-packages/wagtail/wagtailcore/models.py", line 129, in find_for_request
    return get_site_for_hostname(hostname, port)
  File "/home/cityblack1/sites/www.cityblack1.cc/nb/lib/python3.4/site-packages/wagtail/wagtailcore/sites.py", line 38, in get_site_for_hostname
    'root_page'
  File "/home/cityblack1/sites/www.cityblack1.cc/nb/lib/python3.4/site-packages/django/db/models/query.py", line 256, in __iter__
    self._fetch_all()
  File "/home/cityblack1/sites/www.cityblack1.cc/nb/lib/python3.4/site-packages/django/db/models/query.py", line 1085, in _fetch_all
    self._result_cache = list(self.iterator())
  File "/home/cityblack1/sites/www.cityblack1.cc/nb/lib/python3.4/site-packages/django/db/models/query.py", line 54, in __iter__
    results = compiler.execute_sql()
  File "/home/cityblack1/sites/www.cityblack1.cc/nb/lib/python3.4/site-packages/django/db/models/sql/compiler.py", line 835, in execute_sql
    cursor.execute(sql, params)
  File "/home/cityblack1/sites/www.cityblack1.cc/nb/lib/python3.4/site-packages/django/db/backends/utils.py", line 64, in execute
    return self.cursor.execute(sql, params)
  File "/home/cityblack1/sites/www.cityblack1.cc/nb/lib/python3.4/site-packages/django/db/utils.py", line 94, in __exit__
    six.reraise(dj_exc_type, dj_exc_value, traceback)
  File "/home/cityblack1/sites/www.cityblack1.cc/nb/lib/python3.4/site-packages/django/utils/six.py", line 685, in reraise
    raise value.with_traceback(tb)
  File "/home/cityblack1/sites/www.cityblack1.cc/nb/lib/python3.4/site-packages/django/db/backends/utils.py", line 64, in execute
    return self.cursor.execute(sql, params)
  File "/home/cityblack1/sites/www.cityblack1.cc/nb/lib/python3.4/site-packages/django/db/backends/sqlite3/base.py", line 337, in execute
    return Database.Cursor.execute(self, query, params)
django.db.utils.OperationalError: no such table: wagtailcore_site
2017-09-23 15:44:44,093 [b'uWSGIWorker3Core3':140290100131584] [django.request:124] [exception:handle_uncaught_exception] [ERROR]- Internal Server Error: /djangowagtail搭建博客/1wagtail建站分析及博客功能脑图/
Traceback (most recent call last):
  File "/home/cityblack1/sites/www.cityblack1.cc/nb/lib/python3.4/site-packages/django/db/backends/utils.py", line 64, in execute
    return self.cursor.execute(sql, params)
  File "/home/cityblack1/sites/www.cityblack1.cc/nb/lib/python3.4/site-packages/django/db/backends/sqlite3/base.py", line 337, in execute
    return Database.Cursor.execute(self, query, params)
sqlite3.OperationalError: no such table: wagtailcore_site

The above exception was the direct cause of the following exception:

Traceback (most recent call last):
  File "/home/cityblack1/sites/www.cityblack1.cc/nb/lib/python3.4/site-packages/django/core/handlers/exception.py", line 39, in inner
    response = get_response(request)
  File "/home/cityblack1/sites/www.cityblack1.cc/nb/lib/python3.4/site-packages/django/utils/deprecation.py", line 122, in __call__
    response = self.process_request(request)
  File "/home/cityblack1/sites/www.cityblack1.cc/nb/lib/python3.4/site-packages/wagtail/wagtailcore/middleware.py", line 20, in process_request
    request.site = Site.find_for_request(request)
  File "/home/cityblack1/sites/www.cityblack1.cc/nb/lib/python3.4/site-packages/wagtail/wagtailcore/models.py", line 129, in find_for_request
    return get_site_for_hostname(hostname, port)
  File "/home/cityblack1/sites/www.cityblack1.cc/nb/lib/python3.4/site-packages/wagtail/wagtailcore/sites.py", line 38, in get_site_for_hostname
    'root_page'
  File "/home/cityblack1/sites/www.cityblack1.cc/nb/lib/python3.4/site-packages/django/db/models/query.py", line 256, in __iter__
    self._fetch_all()
  File "/home/cityblack1/sites/www.cityblack1.cc/nb/lib/python3.4/site-packages/django/db/models/query.py", line 1085, in _fetch_all
    self._result_cache = list(self.iterator())
  File "/home/cityblack1/sites/www.cityblack1.cc/nb/lib/python3.4/site-packages/django/db/models/query.py", line 54, in __iter__
    results = compiler.execute_sql()
  File "/home/cityblack1/sites/www.cityblack1.cc/nb/lib/python3.4/site-packages/django/db/models/sql/compiler.py", line 835, in execute_sql
    cursor.execute(sql, params)
  File "/home/cityblack1/sites/www.cityblack1.cc/nb/lib/python3.4/site-packages/django/db/backends/utils.py", line 64, in execute
    return self.cursor.execute(sql, params)
  File "/home/cityblack1/sites/www.cityblack1.cc/nb/lib/python3.4/site-packages/django/db/utils.py", line 94, in __exit__
    six.reraise(dj_exc_type, dj_exc_value, traceback)
  File "/home/cityblack1/sites/www.cityblack1.cc/nb/lib/python3.4/site-packages/django/utils/six.py", line 685, in reraise
    raise value.with_traceback(tb)
  File "/home/cityblack1/sites/www.cityblack1.cc/nb/lib/python3.4/site-packages/django/db/backends/utils.py", line 64, in execute
    return self.cursor.execute(sql, params)
  File "/home/cityblack1/sites/www.cityblack1.cc/nb/lib/python3.4/site-packages/django/db/backends/sqlite3/base.py", line 337, in execute
    return Database.Cursor.execute(self, query, params)
django.db.utils.OperationalError: no such table: wagtailcore_site
2017-09-23 15:44:44,637 [b'uWSGIWorker3Core1':140290116916992] [django.request:124] [exception:handle_uncaught_exception] [ERROR]- Internal Server Error: /djangowagtail搭建博客/1wagtail建站分析及博客功能脑图/
Traceback (most recent call last):
  File "/home/cityblack1/sites/www.cityblack1.cc/nb/lib/python3.4/site-packages/django/db/backends/utils.py", line 64, in execute
    return self.cursor.execute(sql, params)
  File "/home/cityblack1/sites/www.cityblack1.cc/nb/lib/python3.4/site-packages/django/db/backends/sqlite3/base.py", line 337, in execute
    return Database.Cursor.execute(self, query, params)
sqlite3.OperationalError: no such table: wagtailcore_site

The above exception was the direct cause of the following exception:

Traceback (most recent call last):
  File "/home/cityblack1/sites/www.cityblack1.cc/nb/lib/python3.4/site-packages/django/core/handlers/exception.py", line 39, in inner
    response = get_response(request)
  File "/home/cityblack1/sites/www.cityblack1.cc/nb/lib/python3.4/site-packages/django/utils/deprecation.py", line 122, in __call__
    response = self.process_request(request)
  File "/home/cityblack1/sites/www.cityblack1.cc/nb/lib/python3.4/site-packages/wagtail/wagtailcore/middleware.py", line 20, in process_request
    request.site = Site.find_for_request(request)
  File "/home/cityblack1/sites/www.cityblack1.cc/nb/lib/python3.4/site-packages/wagtail/wagtailcore/models.py", line 129, in find_for_request
    return get_site_for_hostname(hostname, port)
  File "/home/cityblack1/sites/www.cityblack1.cc/nb/lib/python3.4/site-packages/wagtail/wagtailcore/sites.py", line 38, in get_site_for_hostname
    'root_page'
  File "/home/cityblack1/sites/www.cityblack1.cc/nb/lib/python3.4/site-packages/django/db/models/query.py", line 256, in __iter__
    self._fetch_all()
  File "/home/cityblack1/sites/www.cityblack1.cc/nb/lib/python3.4/site-packages/django/db/models/query.py", line 1085, in _fetch_all
    self._result_cache = list(self.iterator())
  File "/home/cityblack1/sites/www.cityblack1.cc/nb/lib/python3.4/site-packages/django/db/models/query.py", line 54, in __iter__
    results = compiler.execute_sql()
  File "/home/cityblack1/sites/www.cityblack1.cc/nb/lib/python3.4/site-packages/django/db/models/sql/compiler.py", line 835, in execute_sql
    cursor.execute(sql, params)
  File "/home/cityblack1/sites/www.cityblack1.cc/nb/lib/python3.4/site-packages/django/db/backends/utils.py", line 64, in execute
    return self.cursor.execute(sql, params)
  File "/home/cityblack1/sites/www.cityblack1.cc/nb/lib/python3.4/site-packages/django/db/utils.py", line 94, in __exit__
    six.reraise(dj_exc_type, dj_exc_value, traceback)
  File "/home/cityblack1/sites/www.cityblack1.cc/nb/lib/python3.4/site-packages/django/utils/six.py", line 685, in reraise
    raise value.with_traceback(tb)
  File "/home/cityblack1/sites/www.cityblack1.cc/nb/lib/python3.4/site-packages/django/db/backends/utils.py", line 64, in execute
    return self.cursor.execute(sql, params)
  File "/home/cityblack1/sites/www.cityblack1.cc/nb/lib/python3.4/site-packages/django/db/backends/sqlite3/base.py", line 337, in execute
    return Database.Cursor.execute(self, query, params)
django.db.utils.OperationalError: no such table: wagtailcore_site
2017-09-23 15:44:45,408 [b'uWSGIWorker3Core2':140290108524288] [django.request:124] [exception:handle_uncaught_exception] [ERROR]- Internal Server Error: /djangowagtail搭建博客/1wagtail建站分析及博客功能脑图/
Traceback (most recent call last):
  File "/home/cityblack1/sites/www.cityblack1.cc/nb/lib/python3.4/site-packages/django/db/backends/utils.py", line 64, in execute
    return self.cursor.execute(sql, params)
  File "/home/cityblack1/sites/www.cityblack1.cc/nb/lib/python3.4/site-packages/django/db/backends/sqlite3/base.py", line 337, in execute
    return Database.Cursor.execute(self, query, params)
sqlite3.OperationalError: no such table: wagtailcore_site

The above exception was the direct cause of the following exception:

Traceback (most recent call last):
  File "/home/cityblack1/sites/www.cityblack1.cc/nb/lib/python3.4/site-packages/django/core/handlers/exception.py", line 39, in inner
    response = get_response(request)
  File "/home/cityblack1/sites/www.cityblack1.cc/nb/lib/python3.4/site-packages/django/utils/deprecation.py", line 122, in __call__
    response = self.process_request(request)
  File "/home/cityblack1/sites/www.cityblack1.cc/nb/lib/python3.4/site-packages/wagtail/wagtailcore/middleware.py", line 20, in process_request
    request.site = Site.find_for_request(request)
  File "/home/cityblack1/sites/www.cityblack1.cc/nb/lib/python3.4/site-packages/wagtail/wagtailcore/models.py", line 129, in find_for_request
    return get_site_for_hostname(hostname, port)
  File "/home/cityblack1/sites/www.cityblack1.cc/nb/lib/python3.4/site-packages/wagtail/wagtailcore/sites.py", line 38, in get_site_for_hostname
    'root_page'
  File "/home/cityblack1/sites/www.cityblack1.cc/nb/lib/python3.4/site-packages/django/db/models/query.py", line 256, in __iter__
    self._fetch_all()
  File "/home/cityblack1/sites/www.cityblack1.cc/nb/lib/python3.4/site-packages/django/db/models/query.py", line 1085, in _fetch_all
    self._result_cache = list(self.iterator())
  File "/home/cityblack1/sites/www.cityblack1.cc/nb/lib/python3.4/site-packages/django/db/models/query.py", line 54, in __iter__
    results = compiler.execute_sql()
  File "/home/cityblack1/sites/www.cityblack1.cc/nb/lib/python3.4/site-packages/django/db/models/sql/compiler.py", line 835, in execute_sql
    cursor.execute(sql, params)
  File "/home/cityblack1/sites/www.cityblack1.cc/nb/lib/python3.4/site-packages/django/db/backends/utils.py", line 64, in execute
    return self.cursor.execute(sql, params)
  File "/home/cityblack1/sites/www.cityblack1.cc/nb/lib/python3.4/site-packages/django/db/utils.py", line 94, in __exit__
    six.reraise(dj_exc_type, dj_exc_value, traceback)
  File "/home/cityblack1/sites/www.cityblack1.cc/nb/lib/python3.4/site-packages/django/utils/six.py", line 685, in reraise
    raise value.with_traceback(tb)
  File "/home/cityblack1/sites/www.cityblack1.cc/nb/lib/python3.4/site-packages/django/db/backends/utils.py", line 64, in execute
    return self.cursor.execute(sql, params)
  File "/home/cityblack1/sites/www.cityblack1.cc/nb/lib/python3.4/site-packages/django/db/backends/sqlite3/base.py", line 337, in execute
    return Database.Cursor.execute(self, query, params)
django.db.utils.OperationalError: no such table: wagtailcore_site
2017-09-23 15:44:46,141 [b'uWSGIWorker3Core0':140290216888128] [django.request:124] [exception:handle_uncaught_exception] [ERROR]- Internal Server Error: /djangowagtail搭建博客/1wagtail建站分析及博客功能脑图/
Traceback (most recent call last):
  File "/home/cityblack1/sites/www.cityblack1.cc/nb/lib/python3.4/site-packages/django/db/backends/utils.py", line 64, in execute
    return self.cursor.execute(sql, params)
  File "/home/cityblack1/sites/www.cityblack1.cc/nb/lib/python3.4/site-packages/django/db/backends/sqlite3/base.py", line 337, in execute
    return Database.Cursor.execute(self, query, params)
sqlite3.OperationalError: no such table: wagtailcore_site

The above exception was the direct cause of the following exception:

Traceback (most recent call last):
  File "/home/cityblack1/sites/www.cityblack1.cc/nb/lib/python3.4/site-packages/django/core/handlers/exception.py", line 39, in inner
    response = get_response(request)
  File "/home/cityblack1/sites/www.cityblack1.cc/nb/lib/python3.4/site-packages/django/utils/deprecation.py", line 122, in __call__
    response = self.process_request(request)
  File "/home/cityblack1/sites/www.cityblack1.cc/nb/lib/python3.4/site-packages/wagtail/wagtailcore/middleware.py", line 20, in process_request
    request.site = Site.find_for_request(request)
  File "/home/cityblack1/sites/www.cityblack1.cc/nb/lib/python3.4/site-packages/wagtail/wagtailcore/models.py", line 129, in find_for_request
    return get_site_for_hostname(hostname, port)
  File "/home/cityblack1/sites/www.cityblack1.cc/nb/lib/python3.4/site-packages/wagtail/wagtailcore/sites.py", line 38, in get_site_for_hostname
    'root_page'
  File "/home/cityblack1/sites/www.cityblack1.cc/nb/lib/python3.4/site-packages/django/db/models/query.py", line 256, in __iter__
    self._fetch_all()
  File "/home/cityblack1/sites/www.cityblack1.cc/nb/lib/python3.4/site-packages/django/db/models/query.py", line 1085, in _fetch_all
    self._result_cache = list(self.iterator())
  File "/home/cityblack1/sites/www.cityblack1.cc/nb/lib/python3.4/site-packages/django/db/models/query.py", line 54, in __iter__
    results = compiler.execute_sql()
  File "/home/cityblack1/sites/www.cityblack1.cc/nb/lib/python3.4/site-packages/django/db/models/sql/compiler.py", line 835, in execute_sql
    cursor.execute(sql, params)
  File "/home/cityblack1/sites/www.cityblack1.cc/nb/lib/python3.4/site-packages/django/db/backends/utils.py", line 64, in execute
    return self.cursor.execute(sql, params)
  File "/home/cityblack1/sites/www.cityblack1.cc/nb/lib/python3.4/site-packages/django/db/utils.py", line 94, in __exit__
    six.reraise(dj_exc_type, dj_exc_value, traceback)
  File "/home/cityblack1/sites/www.cityblack1.cc/nb/lib/python3.4/site-packages/django/utils/six.py", line 685, in reraise
    raise value.with_traceback(tb)
  File "/home/cityblack1/sites/www.cityblack1.cc/nb/lib/python3.4/site-packages/django/db/backends/utils.py", line 64, in execute
    return self.cursor.execute(sql, params)
  File "/home/cityblack1/sites/www.cityblack1.cc/nb/lib/python3.4/site-packages/django/db/backends/sqlite3/base.py", line 337, in execute
    return Database.Cursor.execute(self, query, params)
django.db.utils.OperationalError: no such table: wagtailcore_site
2017-09-23 15:44:46,649 [b'uWSGIWorker3Core3':140290100131584] [django.request:124] [exception:handle_uncaught_exception] [ERROR]- Internal Server Error: /djangowagtail搭建博客/1wagtail建站分析及博客功能脑图/
Traceback (most recent call last):
  File "/home/cityblack1/sites/www.cityblack1.cc/nb/lib/python3.4/site-packages/django/db/backends/utils.py", line 64, in execute
    return self.cursor.execute(sql, params)
  File "/home/cityblack1/sites/www.cityblack1.cc/nb/lib/python3.4/site-packages/django/db/backends/sqlite3/base.py", line 337, in execute
    return Database.Cursor.execute(self, query, params)
sqlite3.OperationalError: no such table: wagtailcore_site

The above exception was the direct cause of the following exception:

Traceback (most recent call last):
  File "/home/cityblack1/sites/www.cityblack1.cc/nb/lib/python3.4/site-packages/django/core/handlers/exception.py", line 39, in inner
    response = get_response(request)
  File "/home/cityblack1/sites/www.cityblack1.cc/nb/lib/python3.4/site-packages/django/utils/deprecation.py", line 122, in __call__
    response = self.process_request(request)
  File "/home/cityblack1/sites/www.cityblack1.cc/nb/lib/python3.4/site-packages/wagtail/wagtailcore/middleware.py", line 20, in process_request
    request.site = Site.find_for_request(request)
  File "/home/cityblack1/sites/www.cityblack1.cc/nb/lib/python3.4/site-packages/wagtail/wagtailcore/models.py", line 129, in find_for_request
    return get_site_for_hostname(hostname, port)
  File "/home/cityblack1/sites/www.cityblack1.cc/nb/lib/python3.4/site-packages/wagtail/wagtailcore/sites.py", line 38, in get_site_for_hostname
    'root_page'
  File "/home/cityblack1/sites/www.cityblack1.cc/nb/lib/python3.4/site-packages/django/db/models/query.py", line 256, in __iter__
    self._fetch_all()
  File "/home/cityblack1/sites/www.cityblack1.cc/nb/lib/python3.4/site-packages/django/db/models/query.py", line 1085, in _fetch_all
    self._result_cache = list(self.iterator())
  File "/home/cityblack1/sites/www.cityblack1.cc/nb/lib/python3.4/site-packages/django/db/models/query.py", line 54, in __iter__
    results = compiler.execute_sql()
  File "/home/cityblack1/sites/www.cityblack1.cc/nb/lib/python3.4/site-packages/django/db/models/sql/compiler.py", line 835, in execute_sql
    cursor.execute(sql, params)
  File "/home/cityblack1/sites/www.cityblack1.cc/nb/lib/python3.4/site-packages/django/db/backends/utils.py", line 64, in execute
    return self.cursor.execute(sql, params)
  File "/home/cityblack1/sites/www.cityblack1.cc/nb/lib/python3.4/site-packages/django/db/utils.py", line 94, in __exit__
    six.reraise(dj_exc_type, dj_exc_value, traceback)
  File "/home/cityblack1/sites/www.cityblack1.cc/nb/lib/python3.4/site-packages/django/utils/six.py", line 685, in reraise
    raise value.with_traceback(tb)
  File "/home/cityblack1/sites/www.cityblack1.cc/nb/lib/python3.4/site-packages/django/db/backends/utils.py", line 64, in execute
    return self.cursor.execute(sql, params)
  File "/home/cityblack1/sites/www.cityblack1.cc/nb/lib/python3.4/site-packages/django/db/backends/sqlite3/base.py", line 337, in execute
    return Database.Cursor.execute(self, query, params)
django.db.utils.OperationalError: no such table: wagtailcore_site
2017-09-23 15:44:47,061 [b'uWSGIWorker3Core1':140290116916992] [django.request:124] [exception:handle_uncaught_exception] [ERROR]- Internal Server Error: /djangowagtail搭建博客/1wagtail建站分析及博客功能脑图/
Traceback (most recent call last):
  File "/home/cityblack1/sites/www.cityblack1.cc/nb/lib/python3.4/site-packages/django/db/backends/utils.py", line 64, in execute
    return self.cursor.execute(sql, params)
  File "/home/cityblack1/sites/www.cityblack1.cc/nb/lib/python3.4/site-packages/django/db/backends/sqlite3/base.py", line 337, in execute
    return Database.Cursor.execute(self, query, params)
sqlite3.OperationalError: no such table: wagtailcore_site

The above exception was the direct cause of the following exception:

Traceback (most recent call last):
  File "/home/cityblack1/sites/www.cityblack1.cc/nb/lib/python3.4/site-packages/django/core/handlers/exception.py", line 39, in inner
    response = get_response(request)
  File "/home/cityblack1/sites/www.cityblack1.cc/nb/lib/python3.4/site-packages/django/utils/deprecation.py", line 122, in __call__
    response = self.process_request(request)
  File "/home/cityblack1/sites/www.cityblack1.cc/nb/lib/python3.4/site-packages/wagtail/wagtailcore/middleware.py", line 20, in process_request
    request.site = Site.find_for_request(request)
  File "/home/cityblack1/sites/www.cityblack1.cc/nb/lib/python3.4/site-packages/wagtail/wagtailcore/models.py", line 129, in find_for_request
    return get_site_for_hostname(hostname, port)
  File "/home/cityblack1/sites/www.cityblack1.cc/nb/lib/python3.4/site-packages/wagtail/wagtailcore/sites.py", line 38, in get_site_for_hostname
    'root_page'
  File "/home/cityblack1/sites/www.cityblack1.cc/nb/lib/python3.4/site-packages/django/db/models/query.py", line 256, in __iter__
    self._fetch_all()
  File "/home/cityblack1/sites/www.cityblack1.cc/nb/lib/python3.4/site-packages/django/db/models/query.py", line 1085, in _fetch_all
    self._result_cache = list(self.iterator())
  File "/home/cityblack1/sites/www.cityblack1.cc/nb/lib/python3.4/site-packages/django/db/models/query.py", line 54, in __iter__
    results = compiler.execute_sql()
  File "/home/cityblack1/sites/www.cityblack1.cc/nb/lib/python3.4/site-packages/django/db/models/sql/compiler.py", line 835, in execute_sql
    cursor.execute(sql, params)
  File "/home/cityblack1/sites/www.cityblack1.cc/nb/lib/python3.4/site-packages/django/db/backends/utils.py", line 64, in execute
    return self.cursor.execute(sql, params)
  File "/home/cityblack1/sites/www.cityblack1.cc/nb/lib/python3.4/site-packages/django/db/utils.py", line 94, in __exit__
    six.reraise(dj_exc_type, dj_exc_value, traceback)
  File "/home/cityblack1/sites/www.cityblack1.cc/nb/lib/python3.4/site-packages/django/utils/six.py", line 685, in reraise
    raise value.with_traceback(tb)
  File "/home/cityblack1/sites/www.cityblack1.cc/nb/lib/python3.4/site-packages/django/db/backends/utils.py", line 64, in execute
    return self.cursor.execute(sql, params)
  File "/home/cityblack1/sites/www.cityblack1.cc/nb/lib/python3.4/site-packages/django/db/backends/sqlite3/base.py", line 337, in execute
    return Database.Cursor.execute(self, query, params)
django.db.utils.OperationalError: no such table: wagtailcore_site
2017-09-23 15:44:47,341 [b'uWSGIWorker3Core2':140290108524288] [django.request:124] [exception:handle_uncaught_exception] [ERROR]- Internal Server Error: /djangowagtail搭建博客/1wagtail建站分析及博客功能脑图/
Traceback (most recent call last):
  File "/home/cityblack1/sites/www.cityblack1.cc/nb/lib/python3.4/site-packages/django/db/backends/utils.py", line 64, in execute
    return self.cursor.execute(sql, params)
  File "/home/cityblack1/sites/www.cityblack1.cc/nb/lib/python3.4/site-packages/django/db/backends/sqlite3/base.py", line 337, in execute
    return Database.Cursor.execute(self, query, params)
sqlite3.OperationalError: no such table: wagtailcore_site

The above exception was the direct cause of the following exception:

Traceback (most recent call last):
  File "/home/cityblack1/sites/www.cityblack1.cc/nb/lib/python3.4/site-packages/django/core/handlers/exception.py", line 39, in inner
    response = get_response(request)
  File "/home/cityblack1/sites/www.cityblack1.cc/nb/lib/python3.4/site-packages/django/utils/deprecation.py", line 122, in __call__
    response = self.process_request(request)
  File "/home/cityblack1/sites/www.cityblack1.cc/nb/lib/python3.4/site-packages/wagtail/wagtailcore/middleware.py", line 20, in process_request
    request.site = Site.find_for_request(request)
  File "/home/cityblack1/sites/www.cityblack1.cc/nb/lib/python3.4/site-packages/wagtail/wagtailcore/models.py", line 129, in find_for_request
    return get_site_for_hostname(hostname, port)
  File "/home/cityblack1/sites/www.cityblack1.cc/nb/lib/python3.4/site-packages/wagtail/wagtailcore/sites.py", line 38, in get_site_for_hostname
    'root_page'
  File "/home/cityblack1/sites/www.cityblack1.cc/nb/lib/python3.4/site-packages/django/db/models/query.py", line 256, in __iter__
    self._fetch_all()
  File "/home/cityblack1/sites/www.cityblack1.cc/nb/lib/python3.4/site-packages/django/db/models/query.py", line 1085, in _fetch_all
    self._result_cache = list(self.iterator())
  File "/home/cityblack1/sites/www.cityblack1.cc/nb/lib/python3.4/site-packages/django/db/models/query.py", line 54, in __iter__
    results = compiler.execute_sql()
  File "/home/cityblack1/sites/www.cityblack1.cc/nb/lib/python3.4/site-packages/django/db/models/sql/compiler.py", line 835, in execute_sql
    cursor.execute(sql, params)
  File "/home/cityblack1/sites/www.cityblack1.cc/nb/lib/python3.4/site-packages/django/db/backends/utils.py", line 64, in execute
    return self.cursor.execute(sql, params)
  File "/home/cityblack1/sites/www.cityblack1.cc/nb/lib/python3.4/site-packages/django/db/utils.py", line 94, in __exit__
    six.reraise(dj_exc_type, dj_exc_value, traceback)
  File "/home/cityblack1/sites/www.cityblack1.cc/nb/lib/python3.4/site-packages/django/utils/six.py", line 685, in reraise
    raise value.with_traceback(tb)
  File "/home/cityblack1/sites/www.cityblack1.cc/nb/lib/python3.4/site-packages/django/db/backends/utils.py", line 64, in execute
    return self.cursor.execute(sql, params)
  File "/home/cityblack1/sites/www.cityblack1.cc/nb/lib/python3.4/site-packages/django/db/backends/sqlite3/base.py", line 337, in execute
    return Database.Cursor.execute(self, query, params)
django.db.utils.OperationalError: no such table: wagtailcore_site
2017-09-23 15:44:47,573 [b'uWSGIWorker3Core0':140290216888128] [django.request:124] [exception:handle_uncaught_exception] [ERROR]- Internal Server Error: /djangowagtail搭建博客/1wagtail建站分析及博客功能脑图/
Traceback (most recent call last):
  File "/home/cityblack1/sites/www.cityblack1.cc/nb/lib/python3.4/site-packages/django/db/backends/utils.py", line 64, in execute
    return self.cursor.execute(sql, params)
  File "/home/cityblack1/sites/www.cityblack1.cc/nb/lib/python3.4/site-packages/django/db/backends/sqlite3/base.py", line 337, in execute
    return Database.Cursor.execute(self, query, params)
sqlite3.OperationalError: no such table: wagtailcore_site

The above exception was the direct cause of the following exception:

Traceback (most recent call last):
  File "/home/cityblack1/sites/www.cityblack1.cc/nb/lib/python3.4/site-packages/django/core/handlers/exception.py", line 39, in inner
    response = get_response(request)
  File "/home/cityblack1/sites/www.cityblack1.cc/nb/lib/python3.4/site-packages/django/utils/deprecation.py", line 122, in __call__
    response = self.process_request(request)
  File "/home/cityblack1/sites/www.cityblack1.cc/nb/lib/python3.4/site-packages/wagtail/wagtailcore/middleware.py", line 20, in process_request
    request.site = Site.find_for_request(request)
  File "/home/cityblack1/sites/www.cityblack1.cc/nb/lib/python3.4/site-packages/wagtail/wagtailcore/models.py", line 129, in find_for_request
    return get_site_for_hostname(hostname, port)
  File "/home/cityblack1/sites/www.cityblack1.cc/nb/lib/python3.4/site-packages/wagtail/wagtailcore/sites.py", line 38, in get_site_for_hostname
    'root_page'
  File "/home/cityblack1/sites/www.cityblack1.cc/nb/lib/python3.4/site-packages/django/db/models/query.py", line 256, in __iter__
    self._fetch_all()
  File "/home/cityblack1/sites/www.cityblack1.cc/nb/lib/python3.4/site-packages/django/db/models/query.py", line 1085, in _fetch_all
    self._result_cache = list(self.iterator())
  File "/home/cityblack1/sites/www.cityblack1.cc/nb/lib/python3.4/site-packages/django/db/models/query.py", line 54, in __iter__
    results = compiler.execute_sql()
  File "/home/cityblack1/sites/www.cityblack1.cc/nb/lib/python3.4/site-packages/django/db/models/sql/compiler.py", line 835, in execute_sql
    cursor.execute(sql, params)
  File "/home/cityblack1/sites/www.cityblack1.cc/nb/lib/python3.4/site-packages/django/db/backends/utils.py", line 64, in execute
    return self.cursor.execute(sql, params)
  File "/home/cityblack1/sites/www.cityblack1.cc/nb/lib/python3.4/site-packages/django/db/utils.py", line 94, in __exit__
    six.reraise(dj_exc_type, dj_exc_value, traceback)
  File "/home/cityblack1/sites/www.cityblack1.cc/nb/lib/python3.4/site-packages/django/utils/six.py", line 685, in reraise
    raise value.with_traceback(tb)
  File "/home/cityblack1/sites/www.cityblack1.cc/nb/lib/python3.4/site-packages/django/db/backends/utils.py", line 64, in execute
    return self.cursor.execute(sql, params)
  File "/home/cityblack1/sites/www.cityblack1.cc/nb/lib/python3.4/site-packages/django/db/backends/sqlite3/base.py", line 337, in execute
    return Database.Cursor.execute(self, query, params)
django.db.utils.OperationalError: no such table: wagtailcore_site
2017-09-23 15:44:47,781 [b'uWSGIWorker3Core3':140290100131584] [django.request:124] [exception:handle_uncaught_exception] [ERROR]- Internal Server Error: /djangowagtail搭建博客/1wagtail建站分析及博客功能脑图/
Traceback (most recent call last):
  File "/home/cityblack1/sites/www.cityblack1.cc/nb/lib/python3.4/site-packages/django/db/backends/utils.py", line 64, in execute
    return self.cursor.execute(sql, params)
  File "/home/cityblack1/sites/www.cityblack1.cc/nb/lib/python3.4/site-packages/django/db/backends/sqlite3/base.py", line 337, in execute
    return Database.Cursor.execute(self, query, params)
sqlite3.OperationalError: no such table: wagtailcore_site

The above exception was the direct cause of the following exception:

Traceback (most recent call last):
  File "/home/cityblack1/sites/www.cityblack1.cc/nb/lib/python3.4/site-packages/django/core/handlers/exception.py", line 39, in inner
    response = get_response(request)
  File "/home/cityblack1/sites/www.cityblack1.cc/nb/lib/python3.4/site-packages/django/utils/deprecation.py", line 122, in __call__
    response = self.process_request(request)
  File "/home/cityblack1/sites/www.cityblack1.cc/nb/lib/python3.4/site-packages/wagtail/wagtailcore/middleware.py", line 20, in process_request
    request.site = Site.find_for_request(request)
  File "/home/cityblack1/sites/www.cityblack1.cc/nb/lib/python3.4/site-packages/wagtail/wagtailcore/models.py", line 129, in find_for_request
    return get_site_for_hostname(hostname, port)
  File "/home/cityblack1/sites/www.cityblack1.cc/nb/lib/python3.4/site-packages/wagtail/wagtailcore/sites.py", line 38, in get_site_for_hostname
    'root_page'
  File "/home/cityblack1/sites/www.cityblack1.cc/nb/lib/python3.4/site-packages/django/db/models/query.py", line 256, in __iter__
    self._fetch_all()
  File "/home/cityblack1/sites/www.cityblack1.cc/nb/lib/python3.4/site-packages/django/db/models/query.py", line 1085, in _fetch_all
    self._result_cache = list(self.iterator())
  File "/home/cityblack1/sites/www.cityblack1.cc/nb/lib/python3.4/site-packages/django/db/models/query.py", line 54, in __iter__
    results = compiler.execute_sql()
  File "/home/cityblack1/sites/www.cityblack1.cc/nb/lib/python3.4/site-packages/django/db/models/sql/compiler.py", line 835, in execute_sql
    cursor.execute(sql, params)
  File "/home/cityblack1/sites/www.cityblack1.cc/nb/lib/python3.4/site-packages/django/db/backends/utils.py", line 64, in execute
    return self.cursor.execute(sql, params)
  File "/home/cityblack1/sites/www.cityblack1.cc/nb/lib/python3.4/site-packages/django/db/utils.py", line 94, in __exit__
    six.reraise(dj_exc_type, dj_exc_value, traceback)
  File "/home/cityblack1/sites/www.cityblack1.cc/nb/lib/python3.4/site-packages/django/utils/six.py", line 685, in reraise
    raise value.with_traceback(tb)
  File "/home/cityblack1/sites/www.cityblack1.cc/nb/lib/python3.4/site-packages/django/db/backends/utils.py", line 64, in execute
    return self.cursor.execute(sql, params)
  File "/home/cityblack1/sites/www.cityblack1.cc/nb/lib/python3.4/site-packages/django/db/backends/sqlite3/base.py", line 337, in execute
    return Database.Cursor.execute(self, query, params)
django.db.utils.OperationalError: no such table: wagtailcore_site
2017-09-23 15:44:48,021 [b'uWSGIWorker3Core1':140290116916992] [django.request:124] [exception:handle_uncaught_exception] [ERROR]- Internal Server Error: /djangowagtail搭建博客/1wagtail建站分析及博客功能脑图/
Traceback (most recent call last):
  File "/home/cityblack1/sites/www.cityblack1.cc/nb/lib/python3.4/site-packages/django/db/backends/utils.py", line 64, in execute
    return self.cursor.execute(sql, params)
  File "/home/cityblack1/sites/www.cityblack1.cc/nb/lib/python3.4/site-packages/django/db/backends/sqlite3/base.py", line 337, in execute
    return Database.Cursor.execute(self, query, params)
sqlite3.OperationalError: no such table: wagtailcore_site

The above exception was the direct cause of the following exception:

Traceback (most recent call last):
  File "/home/cityblack1/sites/www.cityblack1.cc/nb/lib/python3.4/site-packages/django/core/handlers/exception.py", line 39, in inner
    response = get_response(request)
  File "/home/cityblack1/sites/www.cityblack1.cc/nb/lib/python3.4/site-packages/django/utils/deprecation.py", line 122, in __call__
    response = self.process_request(request)
  File "/home/cityblack1/sites/www.cityblack1.cc/nb/lib/python3.4/site-packages/wagtail/wagtailcore/middleware.py", line 20, in process_request
    request.site = Site.find_for_request(request)
  File "/home/cityblack1/sites/www.cityblack1.cc/nb/lib/python3.4/site-packages/wagtail/wagtailcore/models.py", line 129, in find_for_request
    return get_site_for_hostname(hostname, port)
  File "/home/cityblack1/sites/www.cityblack1.cc/nb/lib/python3.4/site-packages/wagtail/wagtailcore/sites.py", line 38, in get_site_for_hostname
    'root_page'
  File "/home/cityblack1/sites/www.cityblack1.cc/nb/lib/python3.4/site-packages/django/db/models/query.py", line 256, in __iter__
    self._fetch_all()
  File "/home/cityblack1/sites/www.cityblack1.cc/nb/lib/python3.4/site-packages/django/db/models/query.py", line 1085, in _fetch_all
    self._result_cache = list(self.iterator())
  File "/home/cityblack1/sites/www.cityblack1.cc/nb/lib/python3.4/site-packages/django/db/models/query.py", line 54, in __iter__
    results = compiler.execute_sql()
  File "/home/cityblack1/sites/www.cityblack1.cc/nb/lib/python3.4/site-packages/django/db/models/sql/compiler.py", line 835, in execute_sql
    cursor.execute(sql, params)
  File "/home/cityblack1/sites/www.cityblack1.cc/nb/lib/python3.4/site-packages/django/db/backends/utils.py", line 64, in execute
    return self.cursor.execute(sql, params)
  File "/home/cityblack1/sites/www.cityblack1.cc/nb/lib/python3.4/site-packages/django/db/utils.py", line 94, in __exit__
    six.reraise(dj_exc_type, dj_exc_value, traceback)
  File "/home/cityblack1/sites/www.cityblack1.cc/nb/lib/python3.4/site-packages/django/utils/six.py", line 685, in reraise
    raise value.with_traceback(tb)
  File "/home/cityblack1/sites/www.cityblack1.cc/nb/lib/python3.4/site-packages/django/db/backends/utils.py", line 64, in execute
    return self.cursor.execute(sql, params)
  File "/home/cityblack1/sites/www.cityblack1.cc/nb/lib/python3.4/site-packages/django/db/backends/sqlite3/base.py", line 337, in execute
    return Database.Cursor.execute(self, query, params)
django.db.utils.OperationalError: no such table: wagtailcore_site
2017-09-23 15:44:48,209 [b'uWSGIWorker3Core2':140290108524288] [django.request:124] [exception:handle_uncaught_exception] [ERROR]- Internal Server Error: /djangowagtail搭建博客/1wagtail建站分析及博客功能脑图/
Traceback (most recent call last):
  File "/home/cityblack1/sites/www.cityblack1.cc/nb/lib/python3.4/site-packages/django/db/backends/utils.py", line 64, in execute
    return self.cursor.execute(sql, params)
  File "/home/cityblack1/sites/www.cityblack1.cc/nb/lib/python3.4/site-packages/django/db/backends/sqlite3/base.py", line 337, in execute
    return Database.Cursor.execute(self, query, params)
sqlite3.OperationalError: no such table: wagtailcore_site

The above exception was the direct cause of the following exception:

Traceback (most recent call last):
  File "/home/cityblack1/sites/www.cityblack1.cc/nb/lib/python3.4/site-packages/django/core/handlers/exception.py", line 39, in inner
    response = get_response(request)
  File "/home/cityblack1/sites/www.cityblack1.cc/nb/lib/python3.4/site-packages/django/utils/deprecation.py", line 122, in __call__
    response = self.process_request(request)
  File "/home/cityblack1/sites/www.cityblack1.cc/nb/lib/python3.4/site-packages/wagtail/wagtailcore/middleware.py", line 20, in process_request
    request.site = Site.find_for_request(request)
  File "/home/cityblack1/sites/www.cityblack1.cc/nb/lib/python3.4/site-packages/wagtail/wagtailcore/models.py", line 129, in find_for_request
    return get_site_for_hostname(hostname, port)
  File "/home/cityblack1/sites/www.cityblack1.cc/nb/lib/python3.4/site-packages/wagtail/wagtailcore/sites.py", line 38, in get_site_for_hostname
    'root_page'
  File "/home/cityblack1/sites/www.cityblack1.cc/nb/lib/python3.4/site-packages/django/db/models/query.py", line 256, in __iter__
    self._fetch_all()
  File "/home/cityblack1/sites/www.cityblack1.cc/nb/lib/python3.4/site-packages/django/db/models/query.py", line 1085, in _fetch_all
    self._result_cache = list(self.iterator())
  File "/home/cityblack1/sites/www.cityblack1.cc/nb/lib/python3.4/site-packages/django/db/models/query.py", line 54, in __iter__
    results = compiler.execute_sql()
  File "/home/cityblack1/sites/www.cityblack1.cc/nb/lib/python3.4/site-packages/django/db/models/sql/compiler.py", line 835, in execute_sql
    cursor.execute(sql, params)
  File "/home/cityblack1/sites/www.cityblack1.cc/nb/lib/python3.4/site-packages/django/db/backends/utils.py", line 64, in execute
    return self.cursor.execute(sql, params)
  File "/home/cityblack1/sites/www.cityblack1.cc/nb/lib/python3.4/site-packages/django/db/utils.py", line 94, in __exit__
    six.reraise(dj_exc_type, dj_exc_value, traceback)
  File "/home/cityblack1/sites/www.cityblack1.cc/nb/lib/python3.4/site-packages/django/utils/six.py", line 685, in reraise
    raise value.with_traceback(tb)
  File "/home/cityblack1/sites/www.cityblack1.cc/nb/lib/python3.4/site-packages/django/db/backends/utils.py", line 64, in execute
    return self.cursor.execute(sql, params)
  File "/home/cityblack1/sites/www.cityblack1.cc/nb/lib/python3.4/site-packages/django/db/backends/sqlite3/base.py", line 337, in execute
    return Database.Cursor.execute(self, query, params)
django.db.utils.OperationalError: no such table: wagtailcore_site
2017-09-23 15:44:48,417 [b'uWSGIWorker3Core0':140290216888128] [django.request:124] [exception:handle_uncaught_exception] [ERROR]- Internal Server Error: /djangowagtail搭建博客/1wagtail建站分析及博客功能脑图/
Traceback (most recent call last):
  File "/home/cityblack1/sites/www.cityblack1.cc/nb/lib/python3.4/site-packages/django/db/backends/utils.py", line 64, in execute
    return self.cursor.execute(sql, params)
  File "/home/cityblack1/sites/www.cityblack1.cc/nb/lib/python3.4/site-packages/django/db/backends/sqlite3/base.py", line 337, in execute
    return Database.Cursor.execute(self, query, params)
sqlite3.OperationalError: no such table: wagtailcore_site

The above exception was the direct cause of the following exception:

Traceback (most recent call last):
  File "/home/cityblack1/sites/www.cityblack1.cc/nb/lib/python3.4/site-packages/django/core/handlers/exception.py", line 39, in inner
    response = get_response(request)
  File "/home/cityblack1/sites/www.cityblack1.cc/nb/lib/python3.4/site-packages/django/utils/deprecation.py", line 122, in __call__
    response = self.process_request(request)
  File "/home/cityblack1/sites/www.cityblack1.cc/nb/lib/python3.4/site-packages/wagtail/wagtailcore/middleware.py", line 20, in process_request
    request.site = Site.find_for_request(request)
  File "/home/cityblack1/sites/www.cityblack1.cc/nb/lib/python3.4/site-packages/wagtail/wagtailcore/models.py", line 129, in find_for_request
    return get_site_for_hostname(hostname, port)
  File "/home/cityblack1/sites/www.cityblack1.cc/nb/lib/python3.4/site-packages/wagtail/wagtailcore/sites.py", line 38, in get_site_for_hostname
    'root_page'
  File "/home/cityblack1/sites/www.cityblack1.cc/nb/lib/python3.4/site-packages/django/db/models/query.py", line 256, in __iter__
    self._fetch_all()
  File "/home/cityblack1/sites/www.cityblack1.cc/nb/lib/python3.4/site-packages/django/db/models/query.py", line 1085, in _fetch_all
    self._result_cache = list(self.iterator())
  File "/home/cityblack1/sites/www.cityblack1.cc/nb/lib/python3.4/site-packages/django/db/models/query.py", line 54, in __iter__
    results = compiler.execute_sql()
  File "/home/cityblack1/sites/www.cityblack1.cc/nb/lib/python3.4/site-packages/django/db/models/sql/compiler.py", line 835, in execute_sql
    cursor.execute(sql, params)
  File "/home/cityblack1/sites/www.cityblack1.cc/nb/lib/python3.4/site-packages/django/db/backends/utils.py", line 64, in execute
    return self.cursor.execute(sql, params)
  File "/home/cityblack1/sites/www.cityblack1.cc/nb/lib/python3.4/site-packages/django/db/utils.py", line 94, in __exit__
    six.reraise(dj_exc_type, dj_exc_value, traceback)
  File "/home/cityblack1/sites/www.cityblack1.cc/nb/lib/python3.4/site-packages/django/utils/six.py", line 685, in reraise
    raise value.with_traceback(tb)
  File "/home/cityblack1/sites/www.cityblack1.cc/nb/lib/python3.4/site-packages/django/db/backends/utils.py", line 64, in execute
    return self.cursor.execute(sql, params)
  File "/home/cityblack1/sites/www.cityblack1.cc/nb/lib/python3.4/site-packages/django/db/backends/sqlite3/base.py", line 337, in execute
    return Database.Cursor.execute(self, query, params)
django.db.utils.OperationalError: no such table: wagtailcore_site
2017-09-23 15:44:48,821 [b'uWSGIWorker3Core3':140290100131584] [django.request:124] [exception:handle_uncaught_exception] [ERROR]- Internal Server Error: /djangowagtail搭建博客/1wagtail建站分析及博客功能脑图/
Traceback (most recent call last):
  File "/home/cityblack1/sites/www.cityblack1.cc/nb/lib/python3.4/site-packages/django/db/backends/utils.py", line 64, in execute
    return self.cursor.execute(sql, params)
  File "/home/cityblack1/sites/www.cityblack1.cc/nb/lib/python3.4/site-packages/django/db/backends/sqlite3/base.py", line 337, in execute
    return Database.Cursor.execute(self, query, params)
sqlite3.OperationalError: no such table: wagtailcore_site

The above exception was the direct cause of the following exception:

Traceback (most recent call last):
  File "/home/cityblack1/sites/www.cityblack1.cc/nb/lib/python3.4/site-packages/django/core/handlers/exception.py", line 39, in inner
    response = get_response(request)
  File "/home/cityblack1/sites/www.cityblack1.cc/nb/lib/python3.4/site-packages/django/utils/deprecation.py", line 122, in __call__
    response = self.process_request(request)
  File "/home/cityblack1/sites/www.cityblack1.cc/nb/lib/python3.4/site-packages/wagtail/wagtailcore/middleware.py", line 20, in process_request
    request.site = Site.find_for_request(request)
  File "/home/cityblack1/sites/www.cityblack1.cc/nb/lib/python3.4/site-packages/wagtail/wagtailcore/models.py", line 129, in find_for_request
    return get_site_for_hostname(hostname, port)
  File "/home/cityblack1/sites/www.cityblack1.cc/nb/lib/python3.4/site-packages/wagtail/wagtailcore/sites.py", line 38, in get_site_for_hostname
    'root_page'
  File "/home/cityblack1/sites/www.cityblack1.cc/nb/lib/python3.4/site-packages/django/db/models/query.py", line 256, in __iter__
    self._fetch_all()
  File "/home/cityblack1/sites/www.cityblack1.cc/nb/lib/python3.4/site-packages/django/db/models/query.py", line 1085, in _fetch_all
    self._result_cache = list(self.iterator())
  File "/home/cityblack1/sites/www.cityblack1.cc/nb/lib/python3.4/site-packages/django/db/models/query.py", line 54, in __iter__
    results = compiler.execute_sql()
  File "/home/cityblack1/sites/www.cityblack1.cc/nb/lib/python3.4/site-packages/django/db/models/sql/compiler.py", line 835, in execute_sql
    cursor.execute(sql, params)
  File "/home/cityblack1/sites/www.cityblack1.cc/nb/lib/python3.4/site-packages/django/db/backends/utils.py", line 64, in execute
    return self.cursor.execute(sql, params)
  File "/home/cityblack1/sites/www.cityblack1.cc/nb/lib/python3.4/site-packages/django/db/utils.py", line 94, in __exit__
    six.reraise(dj_exc_type, dj_exc_value, traceback)
  File "/home/cityblack1/sites/www.cityblack1.cc/nb/lib/python3.4/site-packages/django/utils/six.py", line 685, in reraise
    raise value.with_traceback(tb)
  File "/home/cityblack1/sites/www.cityblack1.cc/nb/lib/python3.4/site-packages/django/db/backends/utils.py", line 64, in execute
    return self.cursor.execute(sql, params)
  File "/home/cityblack1/sites/www.cityblack1.cc/nb/lib/python3.4/site-packages/django/db/backends/sqlite3/base.py", line 337, in execute
    return Database.Cursor.execute(self, query, params)
django.db.utils.OperationalError: no such table: wagtailcore_site
2017-09-23 15:45:38,129 [b'uWSGIWorker1Core0':140521346242368] [django.request:124] [exception:handle_uncaught_exception] [ERROR]- Internal Server Error: /djangowagtail搭建博客/1wagtail建站分析及博客功能脑图/
Traceback (most recent call last):
  File "/home/cityblack1/sites/www.cityblack1.cc/nb/lib/python3.4/site-packages/django/db/backends/utils.py", line 64, in execute
    return self.cursor.execute(sql, params)
  File "/home/cityblack1/sites/www.cityblack1.cc/nb/lib/python3.4/site-packages/django/db/backends/sqlite3/base.py", line 337, in execute
    return Database.Cursor.execute(self, query, params)
sqlite3.OperationalError: no such table: wagtailcore_site

The above exception was the direct cause of the following exception:

Traceback (most recent call last):
  File "/home/cityblack1/sites/www.cityblack1.cc/nb/lib/python3.4/site-packages/django/core/handlers/exception.py", line 39, in inner
    response = get_response(request)
  File "/home/cityblack1/sites/www.cityblack1.cc/nb/lib/python3.4/site-packages/django/utils/deprecation.py", line 122, in __call__
    response = self.process_request(request)
  File "/home/cityblack1/sites/www.cityblack1.cc/nb/lib/python3.4/site-packages/wagtail/wagtailcore/middleware.py", line 20, in process_request
    request.site = Site.find_for_request(request)
  File "/home/cityblack1/sites/www.cityblack1.cc/nb/lib/python3.4/site-packages/wagtail/wagtailcore/models.py", line 129, in find_for_request
    return get_site_for_hostname(hostname, port)
  File "/home/cityblack1/sites/www.cityblack1.cc/nb/lib/python3.4/site-packages/wagtail/wagtailcore/sites.py", line 38, in get_site_for_hostname
    'root_page'
  File "/home/cityblack1/sites/www.cityblack1.cc/nb/lib/python3.4/site-packages/django/db/models/query.py", line 256, in __iter__
    self._fetch_all()
  File "/home/cityblack1/sites/www.cityblack1.cc/nb/lib/python3.4/site-packages/django/db/models/query.py", line 1085, in _fetch_all
    self._result_cache = list(self.iterator())
  File "/home/cityblack1/sites/www.cityblack1.cc/nb/lib/python3.4/site-packages/django/db/models/query.py", line 54, in __iter__
    results = compiler.execute_sql()
  File "/home/cityblack1/sites/www.cityblack1.cc/nb/lib/python3.4/site-packages/django/db/models/sql/compiler.py", line 835, in execute_sql
    cursor.execute(sql, params)
  File "/home/cityblack1/sites/www.cityblack1.cc/nb/lib/python3.4/site-packages/django/db/backends/utils.py", line 64, in execute
    return self.cursor.execute(sql, params)
  File "/home/cityblack1/sites/www.cityblack1.cc/nb/lib/python3.4/site-packages/django/db/utils.py", line 94, in __exit__
    six.reraise(dj_exc_type, dj_exc_value, traceback)
  File "/home/cityblack1/sites/www.cityblack1.cc/nb/lib/python3.4/site-packages/django/utils/six.py", line 685, in reraise
    raise value.with_traceback(tb)
  File "/home/cityblack1/sites/www.cityblack1.cc/nb/lib/python3.4/site-packages/django/db/backends/utils.py", line 64, in execute
    return self.cursor.execute(sql, params)
  File "/home/cityblack1/sites/www.cityblack1.cc/nb/lib/python3.4/site-packages/django/db/backends/sqlite3/base.py", line 337, in execute
    return Database.Cursor.execute(self, query, params)
django.db.utils.OperationalError: no such table: wagtailcore_site
2017-09-23 15:45:38,853 [b'uWSGIWorker1Core3':140521229485824] [django.request:124] [exception:handle_uncaught_exception] [ERROR]- Internal Server Error: /djangowagtail搭建博客/1wagtail建站分析及博客功能脑图/
Traceback (most recent call last):
  File "/home/cityblack1/sites/www.cityblack1.cc/nb/lib/python3.4/site-packages/django/db/backends/utils.py", line 64, in execute
    return self.cursor.execute(sql, params)
  File "/home/cityblack1/sites/www.cityblack1.cc/nb/lib/python3.4/site-packages/django/db/backends/sqlite3/base.py", line 337, in execute
    return Database.Cursor.execute(self, query, params)
sqlite3.OperationalError: no such table: wagtailcore_site

The above exception was the direct cause of the following exception:

Traceback (most recent call last):
  File "/home/cityblack1/sites/www.cityblack1.cc/nb/lib/python3.4/site-packages/django/core/handlers/exception.py", line 39, in inner
    response = get_response(request)
  File "/home/cityblack1/sites/www.cityblack1.cc/nb/lib/python3.4/site-packages/django/utils/deprecation.py", line 122, in __call__
    response = self.process_request(request)
  File "/home/cityblack1/sites/www.cityblack1.cc/nb/lib/python3.4/site-packages/wagtail/wagtailcore/middleware.py", line 20, in process_request
    request.site = Site.find_for_request(request)
  File "/home/cityblack1/sites/www.cityblack1.cc/nb/lib/python3.4/site-packages/wagtail/wagtailcore/models.py", line 129, in find_for_request
    return get_site_for_hostname(hostname, port)
  File "/home/cityblack1/sites/www.cityblack1.cc/nb/lib/python3.4/site-packages/wagtail/wagtailcore/sites.py", line 38, in get_site_for_hostname
    'root_page'
  File "/home/cityblack1/sites/www.cityblack1.cc/nb/lib/python3.4/site-packages/django/db/models/query.py", line 256, in __iter__
    self._fetch_all()
  File "/home/cityblack1/sites/www.cityblack1.cc/nb/lib/python3.4/site-packages/django/db/models/query.py", line 1085, in _fetch_all
    self._result_cache = list(self.iterator())
  File "/home/cityblack1/sites/www.cityblack1.cc/nb/lib/python3.4/site-packages/django/db/models/query.py", line 54, in __iter__
    results = compiler.execute_sql()
  File "/home/cityblack1/sites/www.cityblack1.cc/nb/lib/python3.4/site-packages/django/db/models/sql/compiler.py", line 835, in execute_sql
    cursor.execute(sql, params)
  File "/home/cityblack1/sites/www.cityblack1.cc/nb/lib/python3.4/site-packages/django/db/backends/utils.py", line 64, in execute
    return self.cursor.execute(sql, params)
  File "/home/cityblack1/sites/www.cityblack1.cc/nb/lib/python3.4/site-packages/django/db/utils.py", line 94, in __exit__
    six.reraise(dj_exc_type, dj_exc_value, traceback)
  File "/home/cityblack1/sites/www.cityblack1.cc/nb/lib/python3.4/site-packages/django/utils/six.py", line 685, in reraise
    raise value.with_traceback(tb)
  File "/home/cityblack1/sites/www.cityblack1.cc/nb/lib/python3.4/site-packages/django/db/backends/utils.py", line 64, in execute
    return self.cursor.execute(sql, params)
  File "/home/cityblack1/sites/www.cityblack1.cc/nb/lib/python3.4/site-packages/django/db/backends/sqlite3/base.py", line 337, in execute
    return Database.Cursor.execute(self, query, params)
django.db.utils.OperationalError: no such table: wagtailcore_site
